<?xml version='1.0'?>

<robot name="diffrobot" xmlns:xacro="http://www.ros.org/wiki/xacro">
    
    <link name="robot_footprint">   <!-- just dumy link before the base link-->
    </link>
    
    <joint name="robot_footprint_joint" type="fixed">
        <parent link="robot_footprint"/>
        <child link="base_link"/>
    </joint>

    <link name="base_link">
        <inertial>
            <origin xyz="0.0 0.0 0.0" rpy="0.0 0.0 0.0"/>
            <mass value="5.0"/>
            <inertia ixx="0.0" ixy="0.0" ixz="0.0" iyy="0.0" iyz="0.0" izz="0.0"/>
        </inertial>
        <visual name="base_link_visual">
            <origin xyz="0.0 0.0 0.0" rpy="0.0 0.0 0.0"/>
            <geometry>
                <box size="0.4 0.2 0.1"/>
            </geometry>
            <material name="">
                <color rgba="0.0 0.0 1.0 1.0"/>
                <texture filename=""/>
            </material>
        </visual>
        <collision>
            <origin xyz="0.0 0.0 0.0" rpy="0.0 0.0 0.0"/>
            <geometry>
                <box size="0.4 0.2 0.1"/>
            </geometry>
        </collision>
    </link>

    <link name="left_wheel">
        <inertial>
            <origin xyz="0.0 0.0 0.0" rpy="0.0 0.0 0.0"/> <!-- origin here from the world -->
            <mass value="0.0"/>
            <inertia ixx="0.0" ixy="0.0" ixz="0.0" iyy="0.0" iyz="0.0" izz="0.0"/>
        </inertial>
        <visual name="left_wheel_visual">
            <origin xyz="0.0 0.0 0.0" rpy="0.0 0.0 0.0"/>
            <geometry>
                <cylinder radius="0.1" length="0.05"/>
            </geometry>
            <material name="">
                <color rgba="1.0 0.0 0.0 1.0"/>
                <texture filename=""/>
            </material>
        </visual>
        <collision>
            <origin xyz="0.0 0.0 0.0" rpy="0.0 0.0 0.0"/>
            <geometry>
                <cylinder radius="0.1" length="0.05"/>
            </geometry>
        </collision>
    </link>

    <joint name="left_wheel_joint" type="continuous">  <!-- continous means that always rotate but revolute means it has a min and max limits-->
        <origin xyz="0.0 0.15 0.0" rpy="1.5707 0.0 0.0" /> <!-- origin here from the parent, base link -->
        <parent link="base_link"/>
        <child link="left_wheel"/>
        <axis xyz="0.0 1.0 0.0"/>    <!-- axis of rotation -->
    </joint>

    <link name="right_wheel">
        <inertial>
            <origin xyz="0.0 0.0 0.0" rpy="0.0 0.0 0.0"/> <!-- origin here from the world -->
            <mass value="0.0"/>
            <inertia ixx="0.0" ixy="0.0" ixz="0.0" iyy="0.0" iyz="0.0" izz="0.0"/>
        </inertial>
        <visual name="right_wheel_visual">
            <origin xyz="0.0 0.0 0.0" rpy="0.0 0.0 0.0"/>
            <geometry>
                <cylinder radius="0.1" length="0.05"/>
            </geometry>
            <material name="">
                <color rgba="1.0 0.0 0.0 1.0"/>
                <texture filename=""/>
            </material>
        </visual>
        <collision>
            <origin xyz="0.0 0.0 0.0" rpy="0.0 0.0 0.0"/>
            <geometry>
                <cylinder radius="0.1" length="0.05"/>
            </geometry>
        </collision>
    </link>

    <joint name="right_wheel_joint" type="continuous">  <!-- continous means that always rotate but revolute means it has a min and max limits-->
        <origin xyz="0.0 -0.15 0.0" rpy="1.5707 0.0 0.0" /> <!-- origin here from the parent, base link 1.5705 is 90 deg -->
        <parent link="base_link"/>
        <child link="right_wheel"/>
        <axis xyz="0.0 1.0 0.0"/>
    </joint>

    <link name="front_caster">
        <inertial>
            <origin xyz="0.0 0.0 0.0" rpy="0.0 0.0 0.0"/>
            <mass value="0.0"/>
            <inertia ixx="0.0" ixy="0.0" ixz="0.0" iyy="0.0" iyz="0.0" izz="0.0"/>
        </inertial>
        <visual name="front_caster_visual">
            <origin xyz="0.0 0.0 0.0" rpy="0.0 0.0 0.0"/>
            <geometry>
                <sphere radius="0.0499"/>
            </geometry>
            <material name="">
                <color rgba="0.0 1.0 0.0 1.0"/>
                <texture filename=""/>
            </material>
        </visual>
        <collision>
            <origin xyz="0.0 0.0 0.0" rpy="0.0 0.0 0.0"/>
            <geometry>
                <sphere radius="0.0499"/>
            </geometry>
        </collision>
    </link>

    <joint name="front_caster_joint" type="fixed">
        <origin xyz="0.15 0.0 -0.05" rpy="0.0 0.0 0.0" /> <!-- origin here from the parent, base link -->
        <parent link="base_link"/>
        <child link="front_caster"/>
    </joint>


    <link name="back_caster">
        <inertial>
            <origin xyz="0.0 0.0 0.0" rpy="0.0 0.0 0.0"/>
            <mass value="0.0"/>
            <inertia ixx="0.0" ixy="0.0" ixz="0.0" iyy="0.0" iyz="0.0" izz="0.0"/>
        </inertial>
        <visual name="back_caster_visual">
            <origin xyz="0.0 0.0 0.0" rpy="0.0 0.0 0.0"/>
            <geometry>
                <sphere radius="0.0499"/>
            </geometry>
            <material name="">
                <color rgba="1.0 0.0 0.0 1.0"/>
                <texture filename=""/>
            </material>
        </visual>
        <collision>
            <origin xyz="0.0 0.0 0.0" rpy="0.0 0.0 0.0"/>
            <geometry>
                <sphere radius="0.0499"/>
            </geometry>
        </collision>
    </link>

    <joint name="back_caster_joint" type="fixed">
        <origin xyz="-0.15 0.0 -0.05" rpy="0.0 0.0 0.0" /> <!-- origin here from the parent, base link -->
        <parent link="base_link"/>
        <child link="back_caster"/>
    </joint>
   
</robot>